Workbook

Sheet 0. Tổng quan
A1: BRIEF TRIỂN KHAI WEBSITE THƯƠNG HIỆU LBCGROUP.VN
A2: Phòng khám Chuyên khoa Da liễu Lạc's Beauty Center · Nền tảng Sapo Web · Giao diện Bean Pharmacity · Lập ngày 22/10/2026
A4: A. THÔNG TIN DỰ ÁN
A5: Tên miền | B5: lbcgroup.vn
A6: Nền tảng / giao diện | B6: Sapo Web – giao diện Bean Pharmacity (Mr. Bean Themes), đã mua.
A7: Link demo giao diện | B7: https://themes.sapo.vn/demo/bean-pharmacity · Bản chạy thử: https://bean-pharmacity.mysapo.net/
A8: Tài liệu cấu hình theme | B8: https://bean-pharmacity.mysapo.net/huong-dan-su-dung (18 module trang chủ, bật/tắt và sắp xếp lại được trong mục Tùy chỉnh giao diện > Trang chủ)
A9: Tên thương hiệu hiển thị | B9: Phòng khám Chuyên khoa Da liễu Lạc's Beauty Center
A10: Hệ sinh thái (5 chuyên khoa/lĩnh vực) | B10: Da liễu · Xét nghiệm · Nhà thuốc · Dược – Mỹ phẩm · Đào tạo nghề
A11: Cơ sở | B11: Cơ sở 01 và Cơ sở 02 (khai trương 29/09/2026) – địa chỉ đầy đủ điền tại sheet 12.
A13: B. ĐỊNH HƯỚNG – MỤC TIÊU
A14: Mục tiêu trọng tâm | B14: THƯƠNG HIỆU, không phải bán hàng. Website là "hồ sơ năng lực" của phòng khám: chứng minh chuyên môn y khoa, công nghệ cao, đội ngũ bác sĩ sau đại học và kết quả điều trị thật.
A15: Mục tiêu phụ | B15: (1) Thu lịch hẹn khám/tư vấn qua form Đặt lịch, hotline, Zalo. (2) Bán dược mỹ phẩm chính hãng – kênh bổ trợ, đặt ở nửa sau trang chủ và menu riêng.
A16: Tỷ trọng trang chủ | B16: ~70% diện tích dành cho thương hiệu – dịch vụ – bác sĩ – công nghệ – kết quả điều trị; ≤30% cho dược mỹ phẩm và tin tức. Toàn bộ khối khuyến mãi/flash sale/mã giảm giá của theme gốc được ẩn (xem sheet 2, phần B).
A17: Đối tượng chính | B17: Khách hàng có vấn đề về da, tóc, lão hóa tại Cần Thơ và các tỉnh miền Tây; học viên quan tâm đào tạo nghề chăm sóc da; đối tác, ứng viên tuyển dụng.
A18: Hành động mong muốn | B18: Đặt lịch khám → Gọi hotline → Chat Zalo/Messenger → Xem hồ sơ bác sĩ / kết quả điều trị → Mua dược mỹ phẩm.
A20: C. NHẬN DIỆN THƯƠNG HIỆU ÁP DỤNG LÊN THEME
A21: Màu chủ đạo | B21: #0E7C86 – xanh y khoa (nút chính, tiêu đề, thanh menu). Thay màu xanh mặc định #1a51a2 của theme tại Thiết lập chung > Màu sắc chủ đạo.
A22: Màu nền | B22: #FFFFFF – trắng (nền chính); #EEF7F8 – xanh rất nhạt (nền các khối xen kẽ, nền đầu trang).
A23: Màu nhấn | B23: #0A4F57 – xanh đậm (trạng thái hover, chữ tiêu đề lớn, số liệu nổi bật). Icon dùng màu #0E7C86. Không dùng màu đỏ/vàng chói kiểu khuyến mãi.
A24: Phông chữ | B24: Tiêu đề: Fraunces (serif) · Nội dung: Be Vietnam Pro. Cả hai có trên Google Fonts, hỗ trợ tiếng Việt. Theme có thể không cho chọn font trong cấu hình → Web/SEO thêm bằng CSS tùy chỉnh (xem sheet 13).
A25: Phong cách hình ảnh | B25: Tông ấm, ánh sáng tự nhiên mềm; không gian phòng khám sạch, gọn; bác sĩ – nhân viên mặc đồng phục đồng bộ. Ưu tiên ảnh chụp thật tại Lạc's; hạn chế ảnh stock, không dùng ảnh người mẫu nước ngoài.
A26: Giọng văn | B26: Chuyên môn – ấm áp – đáng tin. Dùng từ ngữ quen thuộc với khách miền Tây. Không dùng từ tuyệt đối: "tốt nhất", "số 1", "khỏi hẳn", "cam kết 100%", "vĩnh viễn".
A28: D. NGUYÊN TẮC PHÁP LÝ BẮT BUỘC (áp dụng cho mọi nội dung)
A29: Nghị định 342/2025/NĐ-CP | B29: Nội dung về máy móc/công nghệ trình bày dưới dạng "dịch vụ điều trị tại phòng khám", không viết như quảng cáo thiết bị.
A30: Bác sĩ & sản phẩm | B30: KHÔNG dùng tên, hình ảnh, chức danh bác sĩ trên trang/khối dược mỹ phẩm (Điều 8 khoản 4). Bác sĩ chỉ xuất hiện ở nội dung dịch vụ khám chữa bệnh, kèm thông tin đầy đủ (Điều 9).
A31: Before – After | B31: Chỉ đăng khi có văn bản đồng ý của khách hàng (lưu tại sheet 8). Ảnh before-after chỉ dùng cho website/đăng tự nhiên, KHÔNG dùng cho quảng cáo trả phí Facebook.
A32: Nhà thuốc | B32: Chỉ giới thiệu khoa Nhà thuốc; không bán thuốc kê đơn trực tuyến → ẩn trang "Mua thuốc theo đơn" của theme.
A33: Thông tin pháp lý | B33: Chân trang hiển thị: tên pháp nhân, ĐKKD, giấy phép hoạt động khám chữa bệnh, người chịu trách nhiệm chuyên môn, địa chỉ 2 cơ sở. Website có giỏ hàng cần thông báo website TMĐT bán hàng với Bộ Công Thương (online.gov.vn).
A34: Dữ liệu cá nhân | B34: Form đặt lịch có ô đồng ý xử lý dữ liệu cá nhân và đường dẫn Chính sách bảo mật.
A36: E. QUY ƯỚC TRONG FILE
A37: Ô nền xanh nhạt | B37: Thông tin CẦN ĐIỀN / CẦN CHUẨN BỊ (người phụ trách điền trực tiếp vào ô).
A38: Chữ xanh dương | B38: Thông tin cố định đã có từ Marketing (không tự ý sửa).
A39: Cột Trạng thái | B39: Chọn từ danh sách: Chưa bắt đầu / Đang làm / Chờ duyệt / Hoàn thành / Không áp dụng. Bảng tiến độ bên dưới tự cập nhật.
A40: Kích thước ảnh | B40: Là kích thước ĐỀ XUẤT. Trước khi thiết kế, Web/SEO đối chiếu với ảnh mẫu của theme (mở ảnh demo > xem kích thước) để giữ đúng tỉ lệ khung.
A42: F. TIẾN ĐỘ CHUẨN BỊ (tự động)
A43: Hạng mục (sheet) | B43: Mô tả | C43: Tổng đầu việc | D43: Hoàn thành
A44: 1. Sitemap & Menu | B44: Cấu trúc trang & menu | C44: =COUNTA('1. Sitemap & Menu'!I4:I39)-COUNTIF('1. Sitemap & Menu'!I4:I39,"Không áp dụng") -> 36 | D44: =COUNTIF('1. Sitemap & Menu'!I4:I39,"Hoàn thành") -> 0
A45: 2. Bố cục Trang chủ | B45: Khối trang chủ (dùng + ẩn) | C45: =COUNTA('2. Bố cục Trang chủ'!L5:L36)-COUNTIF('2. Bố cục Trang chủ'!L5:L36,"Không áp dụng") -> 30 | D45: =COUNTIF('2. Bố cục Trang chủ'!L5:L36,"Hoàn thành") -> 0
A46: 3. Trang con | B46: Trang con | C46: =COUNTA('3. Trang con'!J4:J22)-COUNTIF('3. Trang con'!J4:J22,"Không áp dụng") -> 19 | D46: =COUNTIF('3. Trang con'!J4:J22,"Hoàn thành") -> 0
...

Sheet 1. Sitemap & Menu
A1: 1. SITEMAP & CẤU TRÚC MENU
A2: Thay toàn bộ menu nhà thuốc của theme gốc (Sản phẩm, Đặt hàng nhanh, Flash Sale, Góc sức khỏe, Đội ngũ dược sĩ…) bằng cấu trúc thương hiệu bên dưới. Menu chính tối đa 9 mục; logo dẫn về Trang chủ.
A3: STT | B3: Cấp 1 (menu chính) | C3: Cấp 2 (mega menu / menu con) | D3: Đường dẫn (slug) | E3: Khung giao diện Sapo | F3: Hiển thị ở | G3: Ghi chú cho Web/SEO | H3: Phụ trách | I3: Trạng thái
A4: 1 | B4: Giới thiệu | D4: /gioi-thieu | E4: page.about | F4: Menu chính, chân trang | G4: Trang tổng quan thương hiệu – chi tiết khối ở sheet 3. | H4: Web/SEO | I4: Chưa bắt đầu
A5: 1.1 | C5: Về Lạc's Beauty Center | D5: /gioi-thieu | E5: page.about | F5: Mega menu | H5: Web/SEO | I5: Chưa bắt đầu
A6: 1.2 | C6: Giá trị cốt lõi | D6: /gioi-thieu#gia-tri-cot-loi | E6: (neo trong trang) | F6: Mega menu | G6: Tạo neo (anchor) tới khối giá trị cốt lõi trên trang Giới thiệu. | H6: Web/SEO | I6: Chưa bắt đầu
A7: 1.3 | C7: Hệ thống cơ sở | D7: /he-thong-co-so | E7: page.he-thong-cua-hang | F7: Mega menu, đầu trang | G7: Thay nút "Hệ thống 8 nhà thuốc" ở đầu trang thành "Hệ thống 2 cơ sở". | H7: Web/SEO | I7: Chưa bắt đầu
A8: 1.4 | C8: Giấy phép hoạt động | D8: /giay-phep-hoat-dong | E8: page (mặc định) | F8: Mega menu, chân trang | G8: Ảnh scan giấy phép KCB, ĐKKD, GCN đủ điều kiện kinh doanh dược. | H8: Web/SEO | I8: Chưa bắt đầu
A9: 1.5 | C9: Tuyển dụng (tùy chọn) | D9: /tuyen-dung | E9: page (mặc định) | F9: Chân trang | G9: Bật khi có tin tuyển dụng. | H9: Web/SEO | I9: Chưa bắt đầu
A10: 2 | B10: Chuyên khoa | D10: (không link – mở mega menu) | F10: Menu chính | G10: Mega menu 5 cột, mỗi cột có icon khoa (sheet 11). | H10: Web/SEO | I10: Chưa bắt đầu
A11: 2.1 | C11: Khoa Da liễu | D11: /khoa-da-lieu | E11: page (mặc định) | F11: Mega menu | H11: Web/SEO | I11: Chưa bắt đầu
A12: 2.2 | C12: Khoa Xét nghiệm | D12: /khoa-xet-nghiem | E12: page (mặc định) | F12: Mega menu | H12: Web/SEO | I12: Chưa bắt đầu
A13: 2.3 | C13: Nhà thuốc | D13: /nha-thuoc | E13: page (mặc định) | F13: Mega menu | G13: Chỉ giới thiệu, không bán thuốc kê đơn online. | H13: Web/SEO | I13: Chưa bắt đầu
A14: 2.4 | C14: Dược – Mỹ phẩm | D14: /duoc-my-pham | E14: collection | F14: Mega menu | G14: Dẫn sang danh mục sản phẩm. | H14: Web/SEO | I14: Chưa bắt đầu
A15: 2.5 | C15: Đào tạo nghề – Lạc's Academy | D15: /dao-tao | E15: page (mặc định) | F15: Mega menu | G15: Cần xác nhận: trang riêng trên lbcgroup.vn hay dẫn sang kênh Academy (sheet 13). | H15: Web/SEO | I15: Chưa bắt đầu
A16: 3 | B16: Dịch vụ điều trị | D16: /dich-vu | E16: blog (danh mục bài) | F16: Menu chính | G16: Mỗi dịch vụ = 1 bài trong blog "dich-vu" để dùng được mục lục tự động + người xét duyệt + bài liên quan. | H16: Web/SEO | I16: Chưa bắt đầu
A17: 3.1 | C17: Điều trị mụn – mụn kháng trị | D17: /dieu-tri-mun | E17: article | F17: Mega menu | H17: Web/SEO | I17: Chưa bắt đầu
A18: 3.2 | C18: Điều trị sẹo | D18: /dieu-tri-seo | E18: article | F18: Mega menu | H18: Web/SEO | I18: Chưa bắt đầu
A19: 3.3 | C19: Điều trị sắc tố – nám – tàn nhang – đồi mồi | D19: /dieu-tri-nam-tan-nhang | E19: article | F19: Mega menu | H19: Web/SEO | I19: Chưa bắt đầu
A20: 3.4 | C20: Điều trị rụng tóc | D20: /dieu-tri-rung-toc | E20: article | F20: Mega menu | H20: Web/SEO | I20: Chưa bắt đầu
A21: 3.5 | C21: Thẩm mỹ nội khoa | D21: /tham-my-noi-khoa | E21: article | F21: Mega menu | H21: Web/SEO | I21: Chưa bắt đầu
A22: 3.6 | C22: Nâng cơ | D22: /nang-co | E22: article | F22: Mega menu | H22: Web/SEO | I22: Chưa bắt đầu
A23: 3.7 | C23: Chăm sóc da chuyên sâu | D23: /cham-soc-da-chuyen-sau | E23: article | F23: Mega menu | H23: Web/SEO | I23: Chưa bắt đầu
A24: 3.8 | C24: Điều trị các bệnh về da khác | D24: /benh-da-lieu-khac | E24: article | F24: Mega menu | H24: Web/SEO | I24: Chưa bắt đầu
A25: 3.9 | C25: Triệt lông | D25: /triet-long | E25: article | F25: Mega menu | H25: Web/SEO | I25: Chưa bắt đầu
A26: 4 | B26: Đội ngũ bác sĩ | D26: /doi-ngu-bac-si | E26: blog.doi_ngu_duoc_si | F26: Menu chính | G26: Dùng khung trang Đội ngũ có sẵn của theme; đổi toàn bộ chữ "dược sĩ" thành "bác sĩ" trong bản dịch theme. | H26: Web/SEO | I26: Chưa bắt đầu
A27: 4.1 | C27: Hồ sơ từng bác sĩ (4 trang) | D27: /bs-[ten-bac-si] | E27: article.duoc_si | F27: Trong trang | H27: Web/SEO | I27: Chưa bắt đầu
A28: 5 | B28: Công nghệ | D28: /cong-nghe | E28: blog (danh mục bài) | F28: Menu chính | G28: Mỗi công nghệ = 1 bài, đặt tên theo dịch vụ điều trị (NĐ 342). | H28: Web/SEO | I28: Chưa bắt đầu
A29: 6 | B29: Kết quả điều trị | D29: /ket-qua-dieu-tri | E29: blog (danh mục bài) | F29: Menu chính | G29: Người thật việc thật. Lọc theo tag dịch vụ. Nếu menu bị tràn dòng ở màn hình 1366px → chuyển mục này vào mega menu Dịch vụ. | H29: Web/SEO | I29: Chưa bắt đầu
A30: 7 | B30: Dược mỹ phẩm | D30: /duoc-my-pham | E30: collection | F30: Menu chính | G30: Mega menu 2 cột: Theo thương hiệu | Theo nhu cầu (sheet 9). | H30: Web/SEO | I30: Chưa bắt đầu
A31: 7.1 | C31: Theo thương hiệu: Bioderma, Biotrade, PostQuam, … | D31: /[ten-thuong-hieu] | E31: collection | F31: Mega menu | H31: Web/SEO | I31: Chưa bắt đầu
A32: 7.2 | C32: Theo nhu cầu: Làm sạch, Đặc trị mụn, Phục hồi, Chống nắng, Sáng da… | D32: /[nhu-cau] | E32: collection | F32: Mega menu | H32: Web/SEO | I32: Chưa bắt đầu
A33: 8 | B33: Tin tức | D33: /tin-tuc | E33: blog | F33: Menu chính | H33: Web/SEO | I33: Chưa bắt đầu
A34: 8.1 | C34: Chăm sóc da | D34: /tin-tuc/cham-soc-da | E34: blog (tag/danh mục) | F34: Mega menu | H34: Web/SEO | I34: Chưa bắt đầu
A35: 8.2 | C35: Hoạt động phòng khám | D35: /tin-tuc/hoat-dong | E35: blog (tag/danh mục) | F35: Mega menu | H35: Web/SEO | I35: Chưa bắt đầu
A36: 9 | B36: Liên hệ | D36: /lien-he | E36: page.contact | F36: Menu chính, chân trang | H36: Web/SEO | I36: Chưa bắt đầu
A37: — | B37: Nút nổi bật đầu trang: ĐẶT LỊCH KHÁM | D37: /dat-lich-kham | E37: page.dat-lich-tu-van | F37: Đầu trang (thay nút "Mua thuốc theo đơn") | G37: Nút màu #0E7C86, luôn hiển thị cả trên mobile. | H37: Web/SEO | I37: Chưa bắt đầu
A38: — | B38: Chân trang | C38: Câu hỏi thường gặp | D38: /cau-hoi-thuong-gap | E38: page.faq | F38: Chân trang | H38: Web/SEO | I38: Chưa bắt đầu
A39: — | B39: Chân trang | C39: Chính sách bảo mật · Thanh toán · Giao hàng · Đổi trả · Điều khoản sử dụng | D39: /chinh-sach-… | E39: page (mặc định) | F39: Chân trang | G39: Bỏ "Chính sách cộng tác viên", "Chương trình cộng tác viên" của theme gốc. | H39: Web/SEO | I39: Chưa bắt đầu

Sheet 2. Bố cục Trang chủ
A1: 2. BỐ CỤC TRANG CHỦ – SẮP XẾP LẠI THỨ TỰ MODULE
A2: Theme cho phép chọn và sắp xếp 18 module tại Tùy chỉnh giao diện > Trang chủ; module không dùng chọn "Không dùng". Thứ tự dưới đây đi từ thương hiệu → chuyên môn → bằng chứng → sản phẩm → tin tức.
A3: Thứ tự mới | B3: Khối nội dung LBC | C3: Module theme dùng lại | D3: Vị trí ở demo gốc | E3: Hành động | F3: Nội dung / trường thông tin cần điền | G3: Hình ảnh cần chuẩn bị | H3: Icon | I3: Nút & liên kết | J3: Ghi chú cho Web/SEO | K3: Phụ trách | L3: Trạng thái
A4: A. CÁC KHỐI SỬ DỤNG – THEO THỨ TỰ HIỂN THỊ MỚI
A5: 0 | B5: Thanh thông báo trên cùng | C5: Đầu trang > Banner top | D5: Trên cùng | E5: Đổi nội dung | F5: 1 dòng thông điệp ngắn (≤ 70 ký tự). Đơn vị sở hữu máy soi da VISIA 3D đầu tiên tại Việt Nam Soi da công nghệ cao - thấy được kết quả trước khi thực hiện | G5: 1 ảnh dải ngang desktop 1920×60 + mobile 750×80, nền #0E7C86, chữ trắng. | H5: — | I5: Link → /dat-lich-kham | J5: Không dùng nội dung mã giảm giá kiểu "Nhập BUY2025". | K5: Web/SEO | L5: Chưa bắt đầu
A6: 1 | B6: Đầu trang (Header) | C6: Đầu trang | D6: Trên cùng | E6: Đổi nội dung | F6: • Logo • Lời chào: (1) LBC xin chào, (2) Hướng đến Y học Cá nhân hóa, (3) Tiên phong trong ứng dụng công nghệ cao • Hotline • Ô tìm kiếm: gợi ý từ khóa = tên dịch vụ & thương hiệu (Trị mụn, Trị nám, Nâng cơ, Triệt lông, Bioderma…) • "Hệ thống 8 nhà thuốc" → "Hệ thống 2 cơ sở" • Giữ biểu tượng tài khoản + giỏ hàng (thu nhỏ) | G6: Logo ngang (PNG nền trong + SVG); logo trắng; ảnh nền đầu trang = màu trắng / xanh rất nhạt #EEF7F8 hoặc hoa văn chìm 1920×(theo ảnh mẫu bg_header). | H6: Icon hotline, cơ sở, tìm kiếm, tài khoản, giỏ hàng (line, màu #0E7C86) | I6: Nút ĐẶT LỊCH KHÁM thay "Mua thuốc theo đơn" | J6: Tắt: Tải ứng dụng, Live, Đặt hàng nhanh, Danh sách yêu thích. | K6: Web/SEO | L6: Chưa bắt đầu
A7: 2 | B7: Menu chính + mega menu | C7: Đầu trang > Thiết lập menu / mega menu | D7: Dưới logo | E7: Đổi nội dung | F7: Theo sheet 1. Mega menu Chuyên khoa (5 cột có icon) và Dịch vụ (9 mục). | G7: — | H7: 5 icon khoa (dùng chung sheet 11) | I7: Theo sheet 1 | J7: Bỏ mục "Danh mục" sản phẩm dạng sidebar của nhà thuốc nếu không cần. | K7: Web/SEO | L7: Chưa bắt đầu
A8: 3 | B8: Hero – Slider thương hiệu | C8: Module Slider (kèm 2 banner phải) | D8: Đầu trang chủ | E8: Đổi nội dung | F8: 3–5 slide, mỗi slide: tiêu đề lớn (≤ 8 từ) + 1 dòng phụ + 1 nút. Đề xuất: S1. Key visual: "Phòng khám Chuyên khoa Da liễu Lạc's Beauty Center" S2. Đội ngũ 4 bác sĩ trình độ sau đại học S3. Tiên phong công nghệ cao S4. Khai trương Cơ sở 02 S5. Lạc's Academy – đào tạo nghề chăm sóc da 2 banner phải: Đặt lịch khám | Dược mỹ phẩm chính hãng. | G8: 5 slide desktop (đề xuất 1600×800 hoặc theo khung slider_1.jpg) + 5 bản mobile (750×900) + 2 banner phải (theo khung banner_right_1.jpg). Chữ tiếng Việt kiểm tra dấu kỹ. | H8: — | I8: S1 → /gioi-thieu · S2 → /doi-ngu-bac-si · S3 → /cong-nghe · S4 → /he-thong-co-so · S5 → /dao-tao | J8: Slide bác sĩ là nội dung dịch vụ KCB – được phép, nhưng không ghép ảnh bác sĩ với sản phẩm mỹ phẩm. | K8: Web/SEO | L8: Chưa bắt đầu | O8: eeeeeeeeeeeeeeeeeeeeeeeeeeeeee
A9: 4 | B9: Giá trị cốt lõi | C9: Module Chính sách (4 ô) | D9: Cuối trang demo | E9: Đổi nội dung + chuyển lên | F9: 4 ô: Tiêu đề (≤ 5 từ) + mô tả 1 câu (≤ 80 ký tự): 1. Tiên phong Công nghệ cao 2. Y học Cá nhân hóa 3. Bác sĩ trình độ sau đại học | G9: — | H9: 4 icon line #0E7C86, 128×128 SVG/PNG | I9: Không bắt buộc | J9: Chuyển từ cuối trang lên ngay dưới slider. | K9: Web/SEO | L9: Chưa bắt đầu
A10: 5 | B10: Về Lạc's Beauty Center | C10: Module Giới thiệu | D10: Giữa trang demo | E10: Đổi nội dung | F10: • Nhãn nhỏ: "Về chúng tôi" • Tiêu đề: tên phòng khám • Đoạn giới thiệu 80–120 từ • 1 số liệu nổi bật (thay "2000+ Khách hàng"): VD số năm hoạt động / số khách đã điều trị – số liệu thật • 3 điểm nhấn kèm ảnh: Đội ngũ chuyên môn | Công nghệ tiên tiến | Không gian chuẩn y khoa (mỗi điểm 1–2 câu) | G10: 1 ảnh lớn (mặt tiền hoặc sảnh) + 3 ảnh nhỏ (bác sĩ đang khám, máy điều trị, phòng điều trị) – 800×600. | H10: — | I10: Xem thêm → /gioi-thieu | J10: Số liệu phải có căn cứ, ghi rõ mốc thời gian nếu cần. | K10: Web/SEO | L10: Chưa bắt đầu
A11: 6 | B11: Hệ sinh thái 5 chuyên khoa | C11: Module Banner 1 (5 banner + chữ, trượt) | D11: Sau Flash sale | E11: Đổi nội dung | F11: 5 thẻ: Da liễu | Xét nghiệm | Nhà thuốc | Dược – Mỹ phẩm | Đào tạo nghề. Mỗi thẻ: nhãn nhỏ (thay "Giảm giá độc quyền" → "Chuyên khoa") + tiêu đề + mô tả 1–2 câu (≤ 120 ký tự) + nút. | G11: 5 ảnh thật của từng khu vực (phòng khám, phòng xét nghiệm, quầy nhà thuốc, kệ mỹ phẩm, lớp học) – theo khung banner mẫu, đề xuất 800×500. | H11: — | I11: Tìm hiểu → trang từng khoa (sheet 1, mục 2.x) | J11: Nhãn nhỏ trong theme đang là chữ cố định → Web/SEO kiểm tra có sửa được trong cấu hình không. | K11: Web/SEO | L11: Chưa bắt đầu
A12: 7 | B12: Dịch vụ điều trị chuyên sâu | C12: Module Danh mục sản phẩm ("Danh mục nổi bật" – lưới 10 ô) | D12: Sau Banner 1 | E12: Đổi nội dung | F12: Tiêu đề khối: "Dịch vụ điều trị chuyên sâu". 9 ô dịch vụ (sheet 5) + ô thứ 10 "Đặt lịch soi da – tư vấn". Mỗi ô: ảnh/icon + tên dịch vụ (≤ 4 từ hiển thị, VD "Trị mụn", "Trị nám – tàn nhang"). | G12: 10 ảnh vuông 300×300 (ảnh minh họa vùng da/khuôn mặt, đồng bộ nền trắng/xanh nhạt) HOẶC 10 icon. | H12: Bộ 9 icon dịch vụ + 1 icon lịch hẹn (sheet 11) | I12: Mỗi ô → bài dịch vụ /dieu-tri-… | J12: Module cho nhập liên kết tự do → trỏ tới bài dịch vụ, không trỏ tới danh mục sản phẩm. Bỏ nút "Xem thêm danh mục" nếu không cần. | K12: Web/SEO | L12: Chưa bắt đầu
A13: 8 | B13: Công nghệ tại phòng khám | C13: Module Banner 2 (5 banner, trượt) | D13: Giữa trang demo | E13: Đổi nội dung | F13: Tiêu đề khối: "Công nghệ cao tại Lạc's" (nếu module không có ô tiêu đề → Web/SEO thêm). 5 banner: mỗi banner ghi tên công nghệ + tên dịch vụ ứng dụng (VD: "Nâng cơ RF Jovena – Dịch vụ nâng cơ, trẻ hóa da"). | G13: 5 banner (ảnh máy trong phòng điều trị thật, có thao tác của nhân viên) – đề xuất 800×500. | H13: — | I13: Mỗi banner → bài công nghệ /cong-nghe/… | J13: Đặt tên theo dịch vụ, không viết kiểu quảng cáo thiết bị (NĐ 342). | K13: Web/SEO | L13: Chưa bắt đầu
A14: 9 | B14: Đội ngũ bác sĩ | C14: Module Tin tức 2 (nguồn: blog "doi-ngu-bac-si") | D14: Gần cuối trang demo | E14: Đổi nội dung + tùy biến | F14: Tiêu đề: "Đội ngũ bác sĩ trình độ sau đại học" + 1 câu dẫn. 4 thẻ: ảnh chân dung, họ tên kèm học vị, chuyên môn chính, nút "Xem hồ sơ". | G14: 4 ảnh chân dung đồng bộ (3:4, 1200×1600, cùng phông nền, cùng ánh sáng). | H14: — | I14: Xem hồ sơ → /bs-…; Xem tất cả → /doi-ngu-bac-si | J14: Module Tin tức 2 hiển thị kiểu 1 bài lớn + danh sách → đề xuất tùy biến hiển thị 4 thẻ ngang giống khối "Đội ngũ chuyên môn" ở trang Giới thiệu của theme (sheet 13). | K14: Web/SEO | L14: Chưa bắt đầu
A15: 10 | B15: Người thật – việc thật (Before/After) | C15: Module Banner 3 (1 banner + chữ) | D15: Sau Tab sản phẩm | E15: Đổi nội dung | F15: • Nhãn nhỏ: "Kết quả điều trị" • Tiêu đề: "Người thật – Việc thật" • Mô tả 1–2 câu • Dòng lưu ý nhỏ: "Kết quả có thể khác nhau tùy cơ địa và mức độ tuân thủ phác đồ." | G15: 1 ảnh ghép before/after đại diện (1200×600) từ ca đã có văn bản đồng ý. | H15: — | I15: Xem kết quả điều trị → /ket-qua-dieu-tri | J15: Chỉ dùng ca có đồng ý bằng văn bản (sheet 8). | K15: Web/SEO | L15: Chưa bắt đầu
A16: 11 | B16: Thương hiệu dược mỹ phẩm chính hãng | C16: Module Thương hiệu | D16: Giữa trang demo | E16: Đổi nội dung | F16: Tiêu đề: "Dược mỹ phẩm chính hãng". 4–5 thẻ thương hiệu: Bioderma, Biotrade, PostQuam, … Mỗi thẻ: ảnh/logo, nhãn (thay "Giảm đến 35%" → "Phân phối chính hãng"), 2 sản phẩm tiêu biểu, số sản phẩm. | G16: Logo thương hiệu PNG nền trong 400×200 + ảnh đại diện thương hiệu (theo khung mẫu). | H16: — | I16: Mỗi thẻ → /[thuong-hieu] | J16: KHÔNG đặt tên/hình bác sĩ trong khối này. | K16: Web/SEO | L16: Chưa bắt đầu
A17: 12 | B17: Sản phẩm tiêu biểu | C17: Module Tab Sản phẩm 1 | D17: Giữa trang demo | E17: Đổi nội dung | F17: Tiêu đề: "Sản phẩm tiêu biểu". Tab theo nhu cầu: Làm sạch | Đặc trị mụn | Phục hồi – dưỡng ẩm | Chống nắng | Sáng da – mờ thâm. 8 sản phẩm/tab. | G17: Ảnh sản phẩm (sheet 9). | H17: — | I17: Xem tất cả → /duoc-my-pham | J17: Tắt thanh "Đã bán", nhãn giảm giá, coupon trên thẻ sản phẩm. | K17: Web/SEO | L17: Chưa bắt đầu
A18: 13 | B18: Tin tức & hoạt động | C18: Module Tin tức (dạng tab) | D18: Gần cuối trang demo | E18: Đổi nội dung | F18: Tiêu đề: "Tin tức & hoạt động". Tab: Bài mới | Chăm sóc da | Hoạt động phòng khám. Tối thiểu 12 bài khi ra mắt (sheet 10). | G18: Ảnh đại diện bài 1200×628. | H18: — | I18: Xem tất cả → /tin-tuc | K18: Web/SEO | L18: Chưa bắt đầu
A19: 14 | B19: Tiện ích cho khách hàng | C19: Module Tiện ích (4 ô) | D19: Sau slider ở demo | E19: Đổi nội dung + chuyển xuống | F19: 4 ô (icon + tiêu đề + mô tả 1 câu + nút): 1. Đặt lịch khám 2. Hỏi đáp chuyên gia 3. Hệ thống cơ sở 4. Tra cứu đơn hàng | G19: 1 banner bên cạnh nếu module yêu cầu (theo khung mẫu). | H19: 4 icon line (sheet 11) | I19: /dat-lich-kham · /cau-hoi-thuong-gap · /he-thong-co-so · tra cứu đơn | J19: Chuyển từ vị trí ngay dưới slider xuống cuối trang để nhường chỗ cho khối thương hiệu. | K19: Web/SEO | L19: Chưa bắt đầu
A20: 15 | B20: Chân trang (Footer) | C20: Chân trang | D20: Cuối trang | E20: Đổi nội dung | F20: • Logo + mô tả 1 câu • Thông tin pháp lý (sheet 12) • Địa chỉ 2 cơ sở, hotline, email, giờ làm việc • Cột: Về Lạc's | Dịch vụ | Chính sách | Hỗ trợ • Mạng xã hội: Fanpage phòng khám, TikTok, Zalo OA, YouTube • Gian hàng: Shopee, TikTok Shop, Lazada, Tiki • Logo "Đã thông báo Bộ Công Thương" (sau khi đăng ký) | G20: Logo trắng, logo BCT, logo phương thức thanh toán. | H20: Icon mạng xã hội & sàn TMĐT (theo bộ có sẵn của theme) | I20: — | J20: Bỏ "Mua hàng qua App/Zalo Mini App", "Chính sách cộng tác viên", dải "Tra cứu hàng đầu" (từ khóa bệnh lý). Đổi dòng bản quyền thành tên công ty. | K20: Web/SEO | L20: Chưa bắt đầu
A21: 16 | B21: Nút liên hệ nổi | C21: Nút liên hệ hỗ trợ | D21: Góc màn hình | E21: Đổi nội dung | F21: Hotline | Zalo | Messenger | Hệ thống cơ sở. Màu nút #0E7C86. | G21: — | H21: Dùng icon có sẵn của theme | I21: tel:, zalo.me/…, m.me/…, /he-thong-co-so | J21: Zalo/Messenger trỏ về kênh của PHÒNG KHÁM, không trỏ kênh cá nhân bác sĩ. | K21: Web/SEO | L21: Chưa bắt đầu
A22: 17 | B22: Popup banner (tùy chọn) | C22: Popup banner khuyến mãi | D22: Khi vào web | E22: Tùy chọn | F22: Chỉ dùng cho sự kiện thương hiệu (VD khai trương Cơ sở 02), hiển thị tối đa 1 lần/ngày. Mặc định TẮT. | G22: 1 ảnh 600×600. | H22: — | I22: → trang sự kiện | K22: Web/SEO | L22: Chưa bắt đầu
A24: B. CÁC MODULE / TÍNH NĂNG ẨN (chọn "Không dùng" hoặc tắt trong cấu hình)
A25: Ẩn | B25: Flash Sale | C25: Module Sản phẩm khuyến mãi | D25: Sau Tiện ích | E25: Ẩn | J25: Định vị thương hiệu y khoa, không chạy giá. Ẩn cả trang /flash-sale và mục menu. | K25: Web/SEO | L25: Chưa bắt đầu
A26: Ẩn | B26: Mã khuyến mãi (coupon) | C26: Module Mã khuyến mãi | D26: Giữa trang | E26: Ẩn | J26: Ẩn cả ở trang danh sách sản phẩm và trang chi tiết sản phẩm. | K26: Web/SEO | L26: Chưa bắt đầu
A27: Ẩn | B27: Sản phẩm theo đối tượng | C27: Module Sản phẩm 1 | D27: Giữa trang | E27: Ẩn | J27: Đã có khối Sản phẩm tiêu biểu. | K27: Web/SEO | L27: Chưa bắt đầu
A28: Ẩn | B28: Sản phẩm theo bệnh lý | C28: Module Sản phẩm 2 | D28: Giữa trang | E28: Ẩn | K28: Web/SEO | L28: Chưa bắt đầu
A29: Ẩn | B29: Tab sản phẩm thứ 2 | C29: Module Tab Sản phẩm 2 | D29: Giữa trang | E29: Ẩn | J29: Giữ tối đa 1 khối sản phẩm trên trang chủ. | K29: Web/SEO | L29: Chưa bắt đầu
A30: Ẩn | B30: Nhóm bệnh theo mùa | C30: Module Nhóm bệnh | D30: Gần cuối | E30: Ẩn | J30: Nội dung nhà thuốc tổng hợp, không phù hợp chuyên khoa da liễu. | K30: Web/SEO | L30: Chưa bắt đầu
A31: Ẩn | B31: Popup sale ảo | C31: Thiết lập Popup sale ảo | D31: Toàn trang | E31: Tắt | J31: Thông báo mua hàng giả lập có thể bị xem là gây hiểu lầm – tắt hẳn. | K31: Web/SEO | L31: Chưa bắt đầu
A32: Ẩn | B32: Tải ứng dụng / Live / Đặt hàng nhanh | C32: Đầu trang | D32: Đầu trang | E32: Tắt | J32: Ẩn cả trang /dat-hang-nhanh. | K32: Web/SEO | L32: Chưa bắt đầu
A33: Ẩn | B33: Mua thuốc theo đơn | C33: Nút đầu trang + trang mua-thuoc-theo-don | D33: Đầu trang | E33: Tắt | J33: Không bán thuốc kê đơn online. Thay vị trí nút bằng ĐẶT LỊCH KHÁM. | K33: Web/SEO | L33: Chưa bắt đầu
A34: Ẩn | B34: Cờ ngôn ngữ (VN/EN) | C34: Popup thông báo & cờ ngôn ngữ | D34: Đầu trang | E34: Tắt | J34: Chưa làm bản tiếng Anh ở giai đoạn ra mắt. | K34: Web/SEO | L34: Chưa bắt đầu
A35: Ẩn | B35: Khối thông tin dược sĩ trên trang sản phẩm | C35: Trang sản phẩm > Khối thông tin dược sĩ | D35: Trang chi tiết SP | E35: Tắt | J35: Tránh xuất hiện nhân sự y tế cạnh sản phẩm mỹ phẩm (NĐ 342, Điều 8 khoản 4). | K35: Web/SEO | L35: Chưa bắt đầu
A36: Ẩn | B36: Danh sách yêu thích, Sản phẩm cùng phân khúc giá | C36: Thiết lập chung / Trang sản phẩm | D36: Toàn trang | E36: Tắt (tùy chọn) | J36: Giảm yếu tố thương mại; có thể bật lại sau. | K36: Web/SEO | L36: Chưa bắt đầu

Sheet 3. Trang con
A2: Mỗi trang tận dụng khung giao diện có sẵn của theme (page.about, page.contact, page.faq, blog.doi_ngu_duoc_si…), chỉ thay nội dung.
A3: STT | B3: Trang | C3: Đường dẫn | D3: Khung giao diện | E3: Các khối nội dung (theo thứ tự) | F3: Trường thông tin cần chuẩn bị | G3: Hình ảnh / icon | H3: Ghi chú cho Web/SEO | I3: Phụ trách | J3: Trạng thái
A4: 1 | B4: Giới thiệu | C4: /gioi-thieu | D4: page.about | E4: 1. Hero: tiêu đề + 1 câu + nút "Đặt lịch khám" 2. "Tại sao chọn Lạc's": 3 ô icon = 3 giá trị cốt lõi 3. Ảnh lớn + đoạn văn về hệ sinh thái 5 chuyên khoa 4. "Về chúng tôi" 3 khối: Câu chuyện thương hiệu | Chúng tôi mang đến | Hành trình phát triển 5. Đội ngũ chuyên môn (4 bác sĩ) | F4: • Câu chuyện thương hiệu (150–250 từ) • Tầm nhìn, sứ mệnh (mỗi ý 1–2 câu) • Mốc phát triển: năm thành lập, mốc Lạc's Academy, khai trương Cơ sở 02 (29/09/2026)… • Đoạn hệ sinh thái (80–120 từ) | G4: Ảnh hero 1920×700; 4 icon giá trị; 1 ảnh lớn 1200×600; 3 ảnh/icon cho 3 khối "Về chúng tôi". | H4: Thay khối "Tại sao chọn chúng tôi" (E-Pharmacy, Tư vấn trực tuyến…) bằng 4 giá trị cốt lõi. | I4: Web/SEO | J4: Chưa bắt đầu
A5: 2 | B5: Khoa Da liễu | C5: /khoa-da-lieu | D5: page (mặc định) | E5: Banner → Giới thiệu khoa → Danh sách dịch vụ thuộc khoa (link 9 bài dịch vụ) → Bác sĩ phụ trách → Trang thiết bị → CTA đặt lịch | F5: Giới thiệu 100–150 từ; phạm vi chuyên môn được cấp phép; danh sách dịch vụ. | G5: Banner 1920×500; 3–4 ảnh phòng khám. | H5: Có thể tái dùng nội dung sheet 4. | I5: Web/SEO | J5: Chưa bắt đầu
A6: 3 | B6: Khoa Xét nghiệm | C6: /khoa-xet-nghiem | D6: page (mặc định) | E6: Banner → Giới thiệu → Danh mục xét nghiệm (bảng) → Quy trình lấy mẫu & trả kết quả → CTA | F6: Danh mục xét nghiệm, thời gian trả kết quả, lưu ý trước xét nghiệm. | G6: Banner; 2–3 ảnh phòng xét nghiệm. | I6: Web/SEO | J6: Chưa bắt đầu
A7: 4 | B7: Nhà thuốc | C7: /nha-thuoc | D7: page (mặc định) | E7: Banner → Giới thiệu nhà thuốc → Tiêu chuẩn (GPP nếu có) → Dược sĩ phụ trách → Giờ mở cửa → CTA liên hệ | F7: Giấy chứng nhận đủ điều kiện kinh doanh dược; tên dược sĩ phụ trách chuyên môn. | G7: Banner; ảnh quầy thuốc. | H7: Không hiển thị giá/giỏ hàng thuốc kê đơn. | I7: Web/SEO | J7: Chưa bắt đầu
A8: 5 | B8: Dược – Mỹ phẩm (giới thiệu) | C8: /duoc-my-pham | D8: collection | E8: Mô tả danh mục ở đầu trang → bộ lọc (thương hiệu, nhu cầu, loại da, giá) → lưới sản phẩm | F8: Mô tả danh mục 60–100 từ: cam kết chính hãng, nguồn nhập. | G8: Banner danh mục 1200×300. | H8: Theme hỗ trợ bộ lọc riêng cho từng danh mục – cấu hình theo sheet 9. | I8: Web/SEO | J8: Chưa bắt đầu
A9: 6 | B9: Đào tạo nghề – Lạc's Academy | C9: /dao-tao | D9: page (mặc định) | E9: Banner → Giới thiệu Academy → Khóa học (chương trình, thời lượng, đầu ra) → Giảng viên → Hình ảnh lớp học → Học viên tiêu biểu → Form/CTA đăng ký tư vấn | F9: Tên khóa (đào tạo sơ cấp Chăm sóc da), nội dung, thời lượng, học phí (nếu công khai), chứng chỉ được cấp, lịch khai giảng. | G9: Banner; 6–9 ảnh lớp học; ảnh giảng viên. | H9: Xác nhận phương án trang (sheet 13). Lead học viên tách riêng lead khách khám. | I9: Web/SEO | J9: Chưa bắt đầu
A10: 7 | B10: Dịch vụ điều trị (9 bài) | C10: /dieu-tri-… (sheet 1) | D10: blog "dich-vu" + article | E10: Mỗi bài: Ảnh bìa → Tóm tắt dịch vụ → Dấu hiệu/đối tượng phù hợp → Nguyên nhân (ngắn) → Phác đồ & quy trình tại Lạc's → Công nghệ áp dụng → Bác sĩ phụ trách → Kết quả điều trị (before/after) → Câu hỏi thường gặp → CTA đặt lịch | F10: Theo sheet 5. | G10: Ảnh bìa 1200×628; 2–4 ảnh trong bài; icon dịch vụ. | H10: Dùng H2/H3 đúng cấp để theme tự tạo mục lục. Bật "người xét duyệt" = bác sĩ tham vấn. KHÔNG chèn shortcode sản phẩm [product …] vào bài có bác sĩ xét duyệt. | I10: Web/SEO | J10: Chưa bắt đầu
A11: 8 | B11: Đội ngũ bác sĩ | C11: /doi-ngu-bac-si | D11: blog.doi_ngu_duoc_si | E11: Lưới thẻ bác sĩ: ảnh, họ tên + học vị, tóm tắt 1 câu, nút Xem chi tiết | F11: Theo sheet 6. | G11: Ảnh chân dung 3:4. | H11: Đổi chữ "Dược sĩ" → "Bác sĩ" ở tiêu đề và nhãn. | I11: Web/SEO | J11: Chưa bắt đầu
A12: 9 | B12: Hồ sơ bác sĩ (4 trang) | C12: /bs-[ten] | D12: article.duoc_si | E12: Ảnh chân dung → Họ tên, học vị, chức danh → Chuyên môn → Quá trình đào tạo → Kinh nghiệm → Chứng chỉ → Dịch vụ phụ trách → Bài viết đã tham vấn | F12: Theo sheet 6. | G12: 1 chân dung + 2–3 ảnh làm việc. | I12: Web/SEO | J12: Chưa bắt đầu
A13: 10 | B13: Công nghệ | C13: /cong-nghe | D13: blog "cong-nghe" + article | E13: Trang danh sách: thẻ công nghệ. Bài chi tiết: dịch vụ ứng dụng → nguyên lý (dễ hiểu) → ưu điểm cho khách → quy trình buổi điều trị → chứng nhận → CTA | F13: Theo sheet 7. | G13: Ảnh thiết bị + ảnh thao tác. | H13: Tiêu đề bài theo tên dịch vụ. | I13: Web/SEO | J13: Chưa bắt đầu
A14: 11 | B14: Kết quả điều trị | C14: /ket-qua-dieu-tri | D14: blog "ket-qua-dieu-tri" + article | E14: Danh sách ca theo tag dịch vụ. Mỗi bài: tình trạng ban đầu → phác đồ → số buổi → ảnh trước/sau → nhận xét của bác sĩ → lưu ý cá thể hóa kết quả | F14: Theo sheet 8. | G14: Ảnh ghép before/after. | H14: Không ghi họ tên đầy đủ khách hàng nếu không được đồng ý. | I14: Web/SEO | J14: Chưa bắt đầu
A15: 12 | B15: Tin tức | C15: /tin-tuc | D15: blog | E15: Danh mục: Chăm sóc da | Hoạt động phòng khám. Bài viết có mục lục, bài liên quan, chia sẻ | F15: Theo sheet 10. | G15: Ảnh đại diện 1200×628. | I15: Web/SEO | J15: Chưa bắt đầu
A16: 13 | B16: Đặt lịch khám | C16: /dat-lich-kham | D16: page.dat-lich-tu-van | E16: Tiêu đề + 1 câu → Form → Hotline/Zalo dự phòng → Địa chỉ 2 cơ sở | F16: Trường form: Họ tên* · SĐT* · Cơ sở muốn đến* · Dịch vụ quan tâm* (danh sách 9 dịch vụ + Khác) · Ngày giờ mong muốn · Ghi chú · Ô đồng ý xử lý dữ liệu cá nhân* | G16: 1 ảnh minh họa không gian tư vấn. | H16: Có thể cần app "Biểu mẫu khảo sát" của Sapo. Xác nhận nơi nhận lead (email/Pancake/CSKH) và quy tắc phân lead (sheet 13). | I16: Web/SEO | J16: Chưa bắt đầu
A17: 14 | B17: Hệ thống cơ sở | C17: /he-thong-co-so | D17: page.he-thong-cua-hang | E17: Danh sách cơ sở + bản đồ Google Maps | F17: Google Sheet theo mẫu theme: address, name, sdt, city, district, url (link nhúng Google Maps – chỉ lấy phần src). | G17: Ảnh mặt tiền từng cơ sở 1200×800. | I17: Web/SEO | J17: Chưa bắt đầu
A18: 15 | B18: Liên hệ | C18: /lien-he | D18: page.contact | E18: Thông tin liên hệ → Form liên hệ → Bản đồ | F18: Hotline, email, giờ làm việc, iframe Google Maps. | G18: — | I18: Web/SEO | J18: Chưa bắt đầu
A19: 16 | B19: Câu hỏi thường gặp | C19: /cau-hoi-thuong-gap | D19: page.faq | E19: Nhóm câu hỏi (H3) → câu hỏi (H4) → trả lời | F19: 4 nhóm: Đặt lịch & thăm khám | Dịch vụ điều trị | Mua hàng & giao hàng | Đào tạo. 5–8 câu/nhóm, bác sĩ duyệt nhóm chuyên môn. | G19: — | H19: Nhập đúng cấu trúc H3/H4 theo hướng dẫn theme. | I19: Web/SEO | J19: Chưa bắt đầu
A20: 17 | B20: Giấy phép hoạt động | C20: /giay-phep-hoat-dong | D20: page (mặc định) | E20: Danh sách giấy phép + ảnh scan | F20: Theo sheet 12. | G20: Ảnh scan rõ nét, có watermark lbcgroup.vn. | I20: Web/SEO | J20: Chưa bắt đầu
A21: 18 | B21: Chính sách (5 trang) | C21: /chinh-sach-… | D21: page (mặc định) | E21: Bảo mật · Thanh toán · Giao hàng · Đổi trả · Điều khoản sử dụng | F21: Nội dung pháp lý từng chính sách. | G21: — | H21: Cần có trước khi thông báo website TMĐT với Bộ Công Thương. | I21: Web/SEO | J21: Chưa bắt đầu
A22: 19 | B22: Trang 404 & tìm kiếm | C22: /404, /search | D22: Mặc định theme | E22: Thông báo + nút về trang chủ + gợi ý dịch vụ | F22: 1 câu thông báo. | G22: — | I22: Web/SEO | J22: Chưa bắt đầu

Sheet 4. ND Chuyên khoa
A1: 4. NỘI DUNG 5 CHUYÊN KHOA / LĨNH VỰC
A2: Điền vào các ô vàng. Nội dung dùng cho khối Hệ sinh thái (trang chủ), mega menu và trang từng khoa.
A3: Trường thông tin | B3: Yêu cầu | C3: Da liễu | D3: Xét nghiệm | E3: Nhà thuốc | F3: Dược – Mỹ phẩm | G3: Đào tạo nghề
A4: Tên hiển thị | B4: ≤ 4 từ | C4: Khoa Da liễu | D4: Khoa Xét nghiệm | E4: Nhà thuốc | F4: Dược – Mỹ phẩm | G4: Đào tạo nghề – Lạc's Academy
A5: Mô tả ngắn (thẻ trang chủ) | B5: ≤ 120 ký tự
A6: Giới thiệu đầy đủ | B6: 100–150 từ
A7: Dịch vụ / hạng mục chính | B7: Liệt kê 3–9 mục
A8: Nhân sự phụ trách | B8: Họ tên, chức danh
A9: Giấy phép liên quan | B9: Số, ngày cấp
A10: Giờ hoạt động | B10: Theo từng cơ sở
A11: Ảnh khu vực (thẻ trang chủ) | B11: 1 ảnh 800×500
A12: Ảnh trang khoa | B12: Banner 1920×500 + 3–4 ảnh
A13: Icon khoa | B13: Mã icon ở sheet 11 | C13: ICO-K1 | D13: ICO-K2 | E13: ICO-K3 | F13: ICO-K4 | G13: ICO-K5
A14: CTA chính | B14: Đặt lịch / Mua hàng / Đăng ký học | C14: Đặt lịch khám | D14: Đặt lịch khám | E14: Liên hệ nhà thuốc | F14: Xem sản phẩm | G14: Đăng ký tư vấn khóa học
A16: Trạng thái từng khoa
A17: Trạng thái | C17: Chưa bắt đầu | D17: Chưa bắt đầu | E17: Chưa bắt đầu | F17: Chưa bắt đầu | G17: Chưa bắt đầu
A18: Phụ trách

Sheet 5. ND Dịch vụ
A1: 5. NỘI DUNG 9 DỊCH VỤ ĐIỀU TRỊ CHUYÊN SÂU
A2: Mỗi dịch vụ = 1 bài trong blog "dich-vu". Bác sĩ duyệt nội dung chuyên môn trước khi đăng. Dòng 1 là ví dụ định dạng (nội dung minh họa, cần bác sĩ viết lại theo thực tế).
A3: STT | B3: Tên dịch vụ (đầy đủ) | C3: Tên ngắn (ô trang chủ) | D3: Slug | E3: Mô tả ngắn (≤ 160 ký tự – dùng làm meta description) | F3: Dấu hiệu / đối tượng phù hợp | G3: Phác đồ & quy trình tại Lạc's (các bước) | H3: Công nghệ áp dụng (sheet 7) | I3: Số buổi / thời gian tham khảo | J3: Bác sĩ phụ trách / tham vấn | K3: Câu hỏi thường gặp (3–5) | L3: Ca before/after (mã sheet 8) | M3: Ảnh bìa 1200×628 | N3: Icon | O3: Từ khóa SEO chính | P3: Phụ trách | Q3: Hạn | R3: Trạng thái
A4: 1 | B4: Điều trị mụn – kể cả mụn kháng trị | C4: Trị mụn | D4: /dieu-tri-mun | E4: Thăm khám và điều trị mụn theo phác đồ cá nhân hóa tại Phòng khám Da liễu Lạc's Beauty Center, Cần Thơ – bác sĩ trực tiếp đánh giá và theo dõi. | F4: Mụn viêm, mụn ẩn, mụn tái phát nhiều lần, mụn đã dùng nhiều sản phẩm không cải thiện… | G4: 1. Soi da – thăm khám 2. Xác định mức độ & nguyên nhân 3. Lập phác đồ cá nhân 4. Điều trị tại phòng khám 5. Tái khám theo lịch | H4: (điền theo sheet 7) | I4: (bác sĩ điền) | J4: (họ tên BS) | K4: Mụn kháng trị là gì? · Bao lâu thì thấy cải thiện? · Có cần kiêng gì khi điều trị? | L4: BA-01, BA-02 | N4: ICO-D1 | O4: điều trị mụn Cần Thơ | R4: Chưa bắt đầu
A5: 2 | B5: Điều trị sẹo | C5: Trị sẹo | D5: /dieu-tri-seo | N5: ICO-D2 | R5: Chưa bắt đầu
A6: 3 | B6: Điều trị sắc tố – nám – tàn nhang – đồi mồi | C6: Trị nám – tàn nhang | D6: /dieu-tri-nam-tan-nhang | N6: ICO-D3 | R6: Chưa bắt đầu
A7: 4 | B7: Điều trị rụng tóc | C7: Trị rụng tóc | D7: /dieu-tri-rung-toc | N7: ICO-D4 | R7: Chưa bắt đầu
A8: 5 | B8: Thẩm mỹ nội khoa | C8: Thẩm mỹ nội khoa | D8: /tham-my-noi-khoa | N8: ICO-D5 | R8: Chưa bắt đầu
A9: 6 | B9: Nâng cơ | C9: Nâng cơ | D9: /nang-co | N9: ICO-D6 | R9: Chưa bắt đầu
A10: 7 | B10: Chăm sóc da chuyên sâu | C10: Chăm sóc da | D10: /cham-soc-da-chuyen-sau | N10: ICO-D7 | R10: Chưa bắt đầu
A11: 8 | B11: Điều trị các bệnh về da khác | C11: Bệnh da khác | D11: /benh-da-lieu-khac | N11: ICO-D8 | R11: Chưa bắt đầu
A12: 9 | B12: Triệt lông | C12: Triệt lông | D12: /triet-long | N12: ICO-D9 | R12: Chưa bắt đầu

Sheet 6. ND Bác sĩ
A1: 6. HỒ SƠ 4 BÁC SĨ TRÌNH ĐỘ SAU ĐẠI HỌC
A2: Dùng cho khối Đội ngũ (trang chủ), trang Đội ngũ, trang hồ sơ và mục "người xét duyệt" của bài viết. Mỗi bác sĩ ký xác nhận nội dung trước khi đăng.
A3: Trường thông tin | B3: Yêu cầu / định dạng | C3: Bác sĩ 1 | D3: Bác sĩ 2 | E3: Bác sĩ 3 | F3: Bác sĩ 4
A4: Họ và tên | B4: Đầy đủ, có dấu
A5: Học vị / trình độ sau đại học | B5: ThS. / BSCKI / BSCKII / TS.
A6: Cách ghi trên web | B6: VD: ThS.BS. Nguyễn Văn A
A7: Chức danh tại Lạc's | B7: VD: Giám đốc chuyên môn
A8: Chuyên khoa | B8: Da liễu / …
A9: Số chứng chỉ hành nghề / giấy phép hành nghề | B9: Số, ngày cấp, nơi cấp
A10: Phạm vi hoạt động chuyên môn | B10: Theo giấy phép
A11: Quá trình đào tạo | B11: Trường – bằng cấp – năm
A12: Chứng chỉ chuyên sâu, hội nghị, đào tạo nước ngoài | B12: Liệt kê
A13: Kinh nghiệm công tác | B13: Số năm
A14: Thế mạnh điều trị (gắn dịch vụ sheet 5) | B14: 2–4 dịch vụ
A15: Triết lý / thông điệp | B15: 1 câu, ≤ 25 từ
... A22: Slug trang hồ sơ | B22: /bs-[ten-khong-dau]
A24: Trạng thái | C24: Chưa bắt đầu | D24: Chưa bắt đầu | E24: Chưa bắt đầu | F24: Chưa bắt đầu
A25: Lưu ý

Sheet 7. ND Công nghệ
A1: 7. CÁC CÔNG NGHỆ TẠI PHÒNG KHÁM
A2: Danh sách dưới đây là KHUNG ĐỀ XUẤT theo nhóm (HIFU, nâng cơ, laser…). Phòng khám cung cấp danh sách máy thực tế; chỉ đăng thiết bị có giấy tờ lưu hành hợp lệ. Đặt tên bài theo dịch vụ (NĐ 342).
A3: Mã | B3: Tên công nghệ hiển thị | C3: Tên thiết bị – hãng – xuất xứ | D3: Dịch vụ điều trị ứng dụng | E3: Nguyên lý (≤ 50 từ, dễ hiểu) | F3: Lợi ích cho khách (3 ý) | G3: Quy trình 1 buổi | H3: Chứng nhận (FDA/CE) & số lưu hành TBYT | I3: Ảnh thiết bị 1200×1200 | J3: Ảnh thao tác 1600×1067 | K3: Video (YouTube ID) | L3: Đưa lên Banner 2 trang chủ? | M3: Phụ trách | N3: Trạng thái
A4: CN-01 | B4: Nâng cơ RF Jovena | D4: Nâng cơ, trẻ hóa da, săn chắc | N4: Chưa bắt đầu
A5: CN-02 | B5: HIFU | D5: Nâng cơ, săn chắc da | N5: Chưa bắt đầu
A6: CN-03 | B6: Laser điều trị sắc tố | D6: Nám, tàn nhang, đồi mồi | N6: Chưa bắt đầu
A7: CN-04 | B7: Công nghệ điều trị sẹo | D7: Sẹo rỗ, sẹo thâm | N7: Chưa bắt đầu
A8: CN-05 | B8: Công nghệ triệt lông | D8: Triệt lông | N8: Chưa bắt đầu
A9: CN-06 | B9: Hệ thống soi – phân tích da | D9: Thăm khám, lập phác đồ cá nhân hóa | N9: Chưa bắt đầu
A10: CN-07 | B10: (bổ sung) | N10: Chưa bắt đầu
A11: CN-08 | B11: (bổ sung) | N11: Chưa bắt đầu

Sheet 8. Before-After
A1: 8. NGƯỜI THẬT – VIỆC THẬT (BEFORE / AFTER)
A2: Mục tiêu khi ra mắt: tối thiểu 10 ca, ưu tiên dịch vụ chủ lực. Chuẩn chụp: cùng góc, cùng khoảng cách, cùng ánh sáng, nền trơn, không filter/chỉnh sửa da. Ca chưa có văn bản đồng ý → KHÔNG đăng.
A3: Mã ca | B3: Dịch vụ | C3: Tình trạng ban đầu | D3: Phác đồ (tóm tắt) | E3: Số buổi / thời gian | F3: Bác sĩ điều trị | G3: Ảnh trước | H3: Ảnh sau | I3: Ảnh trong quá trình | J3: Văn bản đồng ý (Có/Chưa) | K3: Ngày ký | L3: Che nhận diện? | M3: Phạm vi được dùng | N3: Phụ trách | O3: Trạng thái
A4: BA-01 | B4: Điều trị mụn – kể cả mụn kháng trị | J4: Chưa | M4: Website + đăng tự nhiên (KHÔNG dùng quảng cáo trả phí Facebook) | O4: Chưa bắt đầu
A5: BA-02 | B5: Điều trị mụn – kể cả mụn kháng trị | J5: Chưa | M5: Website + đăng tự nhiên (KHÔNG dùng quảng cáo trả phí Facebook) | O5: Chưa bắt đầu
A6: BA-03 | B6: Điều trị sẹo | J6: Chưa | M6: Website + đăng tự nhiên (KHÔNG dùng quảng cáo trả phí Facebook) | O6: Chưa bắt đầu
A7: BA-04 | B7: Điều trị sẹo | J7: Chưa | M7: Website + đăng tự nhiên (KHÔNG dùng quảng cáo trả phí Facebook) | O7: Chưa bắt đầu
A8: BA-05 | B8: Điều trị sắc tố – nám – tàn nhang – đồi mồi | J8: Chưa | M8: Website + đăng tự nhiên (KHÔNG dùng quảng cáo trả phí Facebook) | O8: Chưa bắt đầu
A9: BA-06 | B9: Điều trị sắc tố – nám – tàn nhang – đồi mồi | J9: Chưa | M9: Website + đăng tự nhiên (KHÔNG dùng quảng cáo trả phí Facebook) | O9: Chưa bắt đầu
A10: BA-07 | B10: Nâng cơ | J10: Chưa | M10: Website + đăng tự nhiên (KHÔNG dùng quảng cáo trả phí Facebook) | O10: Chưa bắt đầu
A11: BA-08 | B11: Nâng cơ | J11: Chưa | M11: Website + đăng tự nhiên (KHÔNG dùng quảng cáo trả phí Facebook) | O11: Chưa bắt đầu
A12: BA-09 | B12: Điều trị rụng tóc | J12: Chưa | M12: Website + đăng tự nhiên (KHÔNG dùng quảng cáo trả phí Facebook) | O12: Chưa bắt đầu
A13: BA-10 | B13: Triệt lông | J13: Chưa | M13: Website + đăng tự nhiên (KHÔNG dùng quảng cáo trả phí Facebook) | O13: Chưa bắt đầu
A15: Số ca đã có đồng ý | J15: =COUNTIF(J4:J13,"Có") -> 0

Sheet 9. Dược mỹ phẩm
A1: 9. DƯỢC MỸ PHẨM CHÍNH HÃNG – THƯƠNG HIỆU, DANH MỤC, DỮ LIỆU SẢN PHẨM
A2: Kênh bổ trợ. Tồn kho website quản lý riêng (không đồng bộ với các sàn). Không dùng tên/hình bác sĩ ở bất kỳ vị trí nào trong mục này.
A3: A. THƯƠNG HIỆU (cho Module Thương hiệu trang chủ + trang thương hiệu)
A4: Thương hiệu | B4: Mô tả thương hiệu (50–80 từ) | C4: Xuất xứ | D4: Giấy tờ chứng minh nguồn gốc (hóa đơn NPP / ủy quyền) | E4: Logo PNG nền trong 400×200 | F4: Banner 1200×400 | G4: SP tiêu biểu 1 | H4: SP tiêu biểu 2 | I4: Slug | J4: Phụ trách | K4: Trạng thái
A5: Bioderma | I5: /bioderma | J5: Nhà thuốc + Marketing | K5: Chưa bắt đầu
A6: Biotrade | I6: /biotrade | J6: Nhà thuốc + Marketing | K6: Chưa bắt đầu
A7: PostQuam | I7: /postquam | J7: Nhà thuốc + Marketing | K7: Chưa bắt đầu
A8: (Thương hiệu 4) | J8: Nhà thuốc + Marketing | K8: Chưa bắt đầu
A9: (Thương hiệu 5) | J9: Nhà thuốc + Marketing | K9: Chưa bắt đầu
A11: B. CÂY DANH MỤC SẢN PHẨM (collection) – đề xuất
A12: Nhóm | B12: Danh mục | C12: Slug | D12: Bộ lọc gợi ý
A13: Theo nhu cầu | B13: Làm sạch – tẩy trang | C13: /lam-sach | D13: Thương hiệu · Loại da (dầu/khô/hỗn hợp/nhạy cảm) · Khoảng giá
A14: Theo nhu cầu | B14: Đặc trị mụn | C14: /dac-tri-mun | D14: Thương hiệu · Loại da (dầu/khô/hỗn hợp/nhạy cảm) · Khoảng giá
A15: Theo nhu cầu | B15: Phục hồi – dưỡng ẩm | C15: /phuc-hoi-duong-am | D15: Thương hiệu · Loại da (dầu/khô/hỗn hợp/nhạy cảm) · Khoảng giá
A16: Theo nhu cầu | B16: Chống nắng | C16: /chong-nang | D16: Thương hiệu · Loại da (dầu/khô/hỗn hợp/nhạy cảm) · Khoảng giá
A17: Theo nhu cầu | B17: Sáng da – mờ thâm nám | C17: /sang-da-mo-tham | D17: Thương hiệu · Loại da (dầu/khô/hỗn hợp/nhạy cảm) · Khoảng giá
A18: Theo nhu cầu | B18: Chăm sóc tóc – da đầu | C18: /cham-soc-toc | D18: Thương hiệu · Loại da (dầu/khô/hỗn hợp/nhạy cảm) · Khoảng giá
A19: Theo thương hiệu | B19: Mỗi thương hiệu 1 danh mục (phần A) | C19: /[thuong-hieu] | D19: Thương hiệu · Loại da (dầu/khô/hỗn hợp/nhạy cảm) · Khoảng giá
A20: Tất cả | B20: Dược mỹ phẩm | C20: /duoc-my-pham | D20: Thương hiệu · Loại da (dầu/khô/hỗn hợp/nhạy cảm) · Khoảng giá
A22: C. MẪU DỮ LIỆU SẢN PHẨM – mỗi sản phẩm 1 dòng (dòng đầu là ví dụ định dạng)
A23: SKU (khớp KiotViet) | B23: Tên sản phẩm | C23: Thương hiệu | D23: Danh mục nhu cầu | E23: Loại da | F23: Quy cách (metafield Quycach) | G23: Giá bán (VNĐ) | H23: Giá gốc (nếu có) | I23: Mô tả ngắn (≤ 160 ký tự) | J23: Công dụng | K23: Thành phần chính | L23: Hướng dẫn sử dụng | M23: Lưu ý / chống chỉ định | N23: Số phiếu công bố mỹ phẩm | O23: Xuất xứ | P23: Ảnh (≥ 3 ảnh, 1000×1000, nền trắng) | Q23: Video (YouTube ID) | R23: Trạng thái
A24: (mã KiotViet) | B24: Bioderma Sensibio H2O 500ml | C24: Bioderma | D24: Làm sạch – tẩy trang | E24: Nhạy cảm | F24: Chai 500ml | G24: (theo bảng giá LBC) | I24: Nước tẩy trang dịu nhẹ cho da nhạy cảm… | J24: (theo thông tin hãng) | K24: (theo nhãn) | L24: (theo nhãn) | M24: (theo nhãn) | N24: (số phiếu) | O24: Pháp | P24: 3 ảnh | R24: Ví dụ
R25: Chưa bắt đầu
R26: Chưa bắt đầu
R27: Chưa bắt đầu
R28: Chưa bắt đầu
R29: Chưa bắt đầu
R30: Chưa bắt đầu
R31: Chưa bắt đầu
R32: Chưa bắt đầu
R33: Chưa bắt đầu
R34: Chưa bắt đầu
R35: Chưa bắt đầu
R36: Chưa bắt đầu
... R39: Chưa bắt đầu
A41: D. LƯU Ý
A42: • | B42: Mô tả sản phẩm nhập theo cấu trúc của theme: đoạn mô tả → dòng Heading 6 "Thông số" → bảng 2 cột (để hiển thị thông số rút gọn).
A43: • | B43: Chỉ ghi công dụng đúng với phiếu công bố; không dùng từ "điều trị", "đặc trị khỏi" cho mỹ phẩm.
A44: • | B44: Không gắn hình ảnh, tên, lời khuyên của bác sĩ vào trang sản phẩm; tắt khối thông tin dược sĩ (sheet 2, phần B).
A45: • | B45: Ảnh sản phẩm: chụp thật hoặc ảnh chính thức của hãng (có quyền sử dụng), cùng tỉ lệ vuông, nền trắng.

Sheet 10. Tin tức
A1: 10. KẾ HOẠCH BÀI VIẾT RA MẮT (TỐI THIỂU 12 BÀI)
A2: Tiêu đề là gợi ý, Marketing/Web-SEO điều chỉnh theo bộ từ khóa. Bài chuyên môn dùng H2/H3 để có mục lục; không chèn sản phẩm vào bài có bác sĩ tham vấn.
A3: STT | B3: Chuyên mục | C3: Tiêu đề (đề xuất) | D3: Từ khóa chính | E3: Slug | F3: Số từ | G3: Tác giả | H3: Bác sĩ tham vấn (người xét duyệt) | I3: Ảnh đại diện 1200×628 | J3: Meta description (≤ 160 ký tự) | K3: Ngày đăng | L3: Phụ trách | M3: Trạng thái
A4: 1 | B4: Chăm sóc da | C4: Mụn ẩn, mụn viêm, mụn kháng trị: phân biệt thế nào và khi nào cần gặp bác sĩ da liễu | D4: mụn kháng trị | L4: Marketing | M4: Chưa bắt đầu
A5: 2 | B5: Chăm sóc da | C5: Vì sao mụn cứ tái đi tái lại? Những thói quen chăm sóc da cần xem lại | D5: mụn tái phát | L5: Marketing | M5: Chưa bắt đầu
A6: 3 | B6: Chăm sóc da | C6: Nám, tàn nhang hay đồi mồi? Cách nhận biết các loại tăng sắc tố thường gặp | D6: nám tàn nhang đồi mồi | L6: Marketing | M6: Chưa bắt đầu
A7: 4 | B7: Chăm sóc da | C7: Chống nắng đúng cách cho người sống và làm việc ở miền Tây | D7: kem chống nắng | L7: Marketing | M7: Chưa bắt đầu
A8: 5 | B8: Chăm sóc da | C8: Sẹo rỗ sau mụn: các hướng điều trị tại phòng khám da liễu | D8: điều trị sẹo rỗ | L8: Marketing | M8: Chưa bắt đầu
A9: 6 | B9: Chăm sóc da | C9: Rụng tóc nhiều: những nguyên nhân thường gặp và khi nào cần thăm khám | D9: rụng tóc | L9: Marketing | M9: Chưa bắt đầu
A10: 7 | B10: Chăm sóc da | C10: Quy trình chăm sóc da cơ bản cho da dầu mụn | D10: chăm sóc da dầu mụn | L10: Marketing | M10: Chưa bắt đầu
A11: 8 | B11: Chăm sóc da | C11: Nâng cơ không xâm lấn là gì? Những điều cần biết trước khi thực hiện | D11: nâng cơ không xâm lấn | L11: Marketing | M11: Chưa bắt đầu
A12: 9 | B12: Hoạt động phòng khám | C12: Lạc's Beauty Center khai trương Cơ sở 02 (29/09/2026) | D12: Lạc's Beauty Center | L12: Marketing | M12: Chưa bắt đầu
A13: 10 | B13: Hoạt động phòng khám | C13: Lạc's Academy: lớp đào tạo chăm sóc da (khóa gần nhất) | D13: đào tạo chăm sóc da Cần Thơ | L13: Marketing | M13: Chưa bắt đầu
A14: 11 | B14: Hoạt động phòng khám | C14: Bác sĩ Lạc's tham dự hội nghị / khóa đào tạo chuyên môn (sự kiện gần nhất) | D14: bác sĩ da liễu Cần Thơ | L14: Marketing | M14: Chưa bắt đầu
A15: 12 | B15: Hoạt động phòng khám | C15: Hoạt động cộng đồng / chương trình tư vấn da (sự kiện gần nhất) | D15: phòng khám da liễu Cần Thơ | L15: Marketing | M15: Chưa bắt đầu

Sheet 11. Hình ảnh & Icon
A1: 11. DANH SÁCH HÌNH ẢNH & ICON CẦN CHUẨN BỊ
A2: Ảnh xuất ở 2× kích thước hiển thị, nén ≤ 300KB/ảnh (WebP hoặc JPG chất lượng 80). Đặt tên file không dấu, có từ khóa: vd. dieu-tri-mun-lacs-beauty-center.jpg. Mọi ảnh có văn bản alt.
A3: Mã | B3: Nhóm | C3: Vị trí sử dụng | D3: Mô tả / brief nội dung | E3: Số lượng | F3: Kích thước đề xuất (px) | G3: Định dạng | H3: Nguồn (chụp mới / có sẵn / thiết kế) | I3: Phụ trách | J3: Hạn | K3: Trạng thái
A4: QUY CHUẨN BỘ ICON
B5: Phong cách icon | C5: Toàn site | D5: Icon nét mảnh (line), nét 1px, góc bo tròn, màu #0E7C86 trên nền #EEF7F8; trạng thái hover #0A4F57. Cùng một bộ, không trộn icon nhiều phong cách. Ưu tiên tự vẽ hoặc dùng bộ miễn phí bản quyền thương mại (VD: Phosphor, Lucide). | F5: 128×128 (hiển thị 48–64) | G5: SVG + PNG | H5: Thiết kế | I5: Thiết kế
A6: ICON
A7: ICO-V1 | B7: Icon | C7: Giá trị cốt lõi | D7: Tiên phong công nghệ cao (gợi ý hình: tia sáng / chip) | E7: 1 | F7: 128×128 | G7: SVG + PNG | H7: Thiết kế | I7: Thiết kế | K7: Chưa bắt đầu
A8: ICO-V2 | B8: Icon | C8: Giá trị cốt lõi | D8: Y học cá nhân hóa (gợi ý: dấu vân tay / hồ sơ cá nhân) | E8: 1 | F8: 128×128 | G8: SVG + PNG | H8: Thiết kế | I8: Thiết kế | K8: Chưa bắt đầu
A9: ICO-V3 | B9: Icon | C9: Giá trị cốt lõi | D9: Bác sĩ sau đại học (gợi ý: ống nghe + mũ tốt nghiệp) | E9: 1 | F9: 128×128 | G9: SVG + PNG | H9: Thiết kế | I9: Thiết kế | K9: Chưa bắt đầu
A10: ICO-V4 | B10: Icon | C10: Giá trị cốt lõi | D10: Dược mỹ phẩm chính hãng (gợi ý: khiên + lọ mỹ phẩm) – nếu dùng ô thứ 4 | E10: 1 | F10: 128×128 | G10: SVG + PNG | H10: Thiết kế | I10: Thiết kế | K10: Chưa bắt đầu
A11: ICO-K1→K5 | B11: Icon | C11: Mega menu Chuyên khoa, trang khoa | D11: Da liễu · Xét nghiệm (ống nghiệm) · Nhà thuốc (viên thuốc/chữ thập) · Dược – Mỹ phẩm (lọ serum) · Đào tạo nghề (mũ tốt nghiệp) | E11: 5 | F11: 128×128 | G11: SVG + PNG | H11: Thiết kế | I11: Thiết kế | K11: Chưa bắt đầu
A12: ICO-D1→D9 | B12: Icon | C12: Khối Dịch vụ trang chủ, mega menu Dịch vụ | D12: Mụn · Sẹo · Sắc tố/nám · Rụng tóc · Thẩm mỹ nội khoa · Nâng cơ · Chăm sóc da · Bệnh da khác · Triệt lông | E12: 9 | F12: 128×128 | G12: SVG + PNG | H12: Thiết kế | I12: Thiết kế | K12: Chưa bắt đầu
A13: ICO-D10 | B13: Icon | C13: Ô thứ 10 khối Dịch vụ | D13: Đặt lịch soi da – tư vấn (lịch + kính lúp) | E13: 1 | F13: 128×128 | G13: SVG + PNG | H13: Thiết kế | I13: Thiết kế | K13: Chưa bắt đầu
A14: ICO-T1→T4 | B14: Icon | C14: Khối Tiện ích | D14: Đặt lịch khám · Hỏi đáp chuyên gia · Hệ thống cơ sở · Tra cứu đơn hàng | E14: 4 | F14: 128×128 | G14: SVG + PNG | H14: Thiết kế | I14: Thiết kế | K14: Chưa bắt đầu
A15: ICO-A1→A3 | B15: Icon/ảnh | C15: Trang Giới thiệu – khối "Về chúng tôi" | D15: Câu chuyện thương hiệu · Chúng tôi mang đến · Hành trình phát triển | E15: 3 | F15: theo ảnh mẫu about4_icon | G15: PNG/JPG | H15: Thiết kế | I15: Thiết kế | K15: Chưa bắt đầu
A16: NHẬN DIỆN
A17: BR-01 | B17: Logo | C17: Đầu trang | D17: Logo ngang màu chính, nền trong suốt | E17: 1 | F17: Cao ≥ 120 (bản 2×) + SVG | G17: SVG + PNG | H17: Có sẵn | I17: Marketing | K17: Chưa bắt đầu
A18: BR-02 | B18: Logo | C18: Chân trang, nền tối | D18: Logo trắng | E18: 1 | F18: Cao ≥ 120 + SVG | G18: SVG + PNG | H18: Có sẵn | I18: Marketing | K18: Chưa bắt đầu
A19: BR-03 | B19: Favicon | C19: Tab trình duyệt | D19: Biểu tượng rút gọn từ logo | E19: 1 | F19: 512×512 | G19: PNG | H19: Thiết kế | I19: Thiết kế | K19: Chưa bắt đầu
A20: BR-04 | B20: Ảnh chia sẻ (OG) | C20: Khi chia sẻ link lên Facebook/Zalo | D20: Logo + tên phòng khám trên nền thương hiệu | E20: 1 | F20: 1200×630 | G20: JPG | H20: Thiết kế | I20: Thiết kế | K20: Chưa bắt đầu
A21: BR-05 | B21: Ảnh nền đầu trang | C21: Header | D21: Màu trắng / xanh rất nhạt hoặc hoa văn chìm rất nhẹ | E21: 1 | F21: Theo ảnh mẫu bg_header | G21: JPG | H21: Thiết kế | I21: Thiết kế | K21: Chưa bắt đầu
A22: TRANG CHỦ
A23: HP-01 | B23: Banner top | C23: Thanh thông báo | D23: Thông điệp khai trương CS02 / đặt lịch | E23: 2 | F23: 1920×60 + 750×80 | G23: JPG | H23: Thiết kế | I23: Thiết kế | K23: Chưa bắt đầu
A24: HP-02 | B24: Slider | C24: Hero | D24: 5 slide (thương hiệu, bác sĩ, công nghệ, Cơ sở 02, Academy) – desktop | E24: 5 | F24: 1600×800 (đối chiếu slider_1.jpg) | G24: JPG/WebP | H24: Thiết kế + chụp mới | I24: Marketing | K24: Chưa bắt đầu
A25: HP-03 | B25: Slider mobile | C25: Hero (mobile) | D25: Bản dọc tương ứng 5 slide | E25: 5 | F25: 750×900 | G25: JPG/WebP | H25: Thiết kế | I25: Thiết kế | K25: Chưa bắt đầu
A26: HP-04 | B26: Banner phải slider | C26: Hero | D26: Đặt lịch khám · Dược mỹ phẩm chính hãng | E26: 2 | F26: Theo banner_right_1.jpg | G26: JPG | H26: Thiết kế | I26: Thiết kế | K26: Chưa bắt đầu
A27: HP-05 | B27: Ảnh Giới thiệu | C27: Khối Về Lạc's | D27: 1 ảnh lớn mặt tiền/sảnh + 3 ảnh nhỏ (BS đang khám, máy, phòng điều trị) | E27: 4 | F27: 1200×800 / 800×600 | G27: JPG | H27: Chụp mới | I27: Marketing | K27: Chưa bắt đầu
A28: HP-06 | B28: Ảnh 5 chuyên khoa | C28: Khối Hệ sinh thái (Banner 1) | D28: Ảnh thật từng khu vực: phòng khám, xét nghiệm, nhà thuốc, kệ mỹ phẩm, lớp học | E28: 5 | F28: 800×500 | G28: JPG | H28: Chụp mới | I28: Marketing | K28: Chưa bắt đầu
A29: HP-07 | B29: Ảnh 10 ô dịch vụ | C29: Khối Dịch vụ | D29: Ảnh vuông đồng bộ nền trắng/xanh nhạt (nếu không dùng icon) | E29: 10 | F29: 300×300 | G29: JPG/PNG | I29: Marketing | K29: Chưa bắt đầu
A30: HP-08 | B30: Banner công nghệ | C30: Khối Công nghệ (Banner 2) | D30: Ảnh máy trong phòng điều trị + tên công nghệ & dịch vụ | E30: 5 | F30: 800×500 | G30: JPG | H30: Chụp mới + thiết kế | I30: Marketing | K30: Chưa bắt đầu
A31: HP-09 | B31: Before/After đại diện | C31: Khối Người thật – việc thật (Banner 3) | D31: Ảnh ghép trước/sau từ ca có đồng ý | E31: 1 | F31: 1200×600 | G31: JPG | H31: Thiết kế từ ảnh ca | I31: Marketing | K31: Chưa bắt đầu
A32: HP-10 | B32: Thẻ thương hiệu | C32: Khối Thương hiệu | D32: Logo/ảnh đại diện mỗi thương hiệu | E32: 5 | F32: Theo khung mẫu; logo 400×200 | G32: PNG | H32: Có sẵn từ hãng | I32: Marketing | K32: Chưa bắt đầu
A33: CON NGƯỜI & KHÔNG GIAN
A34: PP-01 | B34: Chân dung bác sĩ | C34: Trang chủ, Đội ngũ, hồ sơ, slider | D34: 4 bác sĩ, cùng phông nền, áo blouse, ánh sáng đồng bộ | E34: 4 | F34: 1200×1600 (3:4) | G34: JPG | H34: Chụp mới | I34: Marketing | K34: Chưa bắt đầu
A35: PP-02 | B35: Ảnh tập thể bác sĩ | C35: Slider S2, trang Giới thiệu | D35: (có thể ghép từ ảnh tách nền) | E35: 1 | F35: 1920×1080 | G35: JPG | H35: Chụp mới | I35: Marketing | K35: Chưa bắt đầu
A36: PP-03 | B36: Ảnh bác sĩ làm việc | C36: Hồ sơ BS, bài dịch vụ | D36: Đang soi da, tư vấn, thao tác máy | E36: 10 | F36: 1600×1067 | G36: JPG | H36: Chụp mới | I36: Marketing | K36: Chưa bắt đầu
A37: PP-04 | B37: Mặt tiền 2 cơ sở | C37: Hệ thống cơ sở, Giới thiệu | D37: Ban ngày, thấy rõ biển hiệu | E37: 2 | F37: 1200×800 | G37: JPG | H37: Chụp mới | I37: Marketing | K37: Chưa bắt đầu
A38: PP-05 | B38: Không gian nội thất | C38: Giới thiệu, trang khoa | D38: Sảnh, phòng tư vấn, phòng điều trị, phòng xét nghiệm, nhà thuốc, phòng học | E38: 12 | F38: 1600×1067 | G38: JPG | H38: Chụp mới | I38: Marketing | K38: Chưa bắt đầu
A39: PP-06 | B39: Ảnh lớp học Academy | C39: Trang Đào tạo | D39: Giờ thực hành, lễ trao chứng chỉ | E39: 9 | F39: 1600×1067 | G39: JPG | H39: Có sẵn / chụp mới | I39: Marketing | K39: Chưa bắt đầu
A40: TRANG CON & BÀI VIẾT
...

Sheet 12. Thông tin & Pháp lý
A1: 12. THÔNG TIN CHUNG, PHÁP LÝ, KÊNH LIÊN KẾT & CÔNG CỤ ĐO LƯỜNG
A2: Điền đầy đủ trước khi Web/SEO cấu hình chân trang, trang Liên hệ, Hệ thống cơ sở và mã theo dõi.
A3: Nhóm | B3: Trường thông tin | C3: Giá trị | D3: Hiển thị ở | E3: Ghi chú
A4: Pháp lý | B4: Tên pháp nhân (công ty) | C4: CÔNG TY TNHH VIỆN CHĂM SÓC DA LẠC'S BEAUTY CENTER | D4: Chân trang, Giấy phép
A5: Pháp lý | B5: Mã số doanh nghiệp / ĐKKD – ngày cấp – nơi cấp | D5: Chân trang
A6: Pháp lý | B6: Tên cơ sở KCB theo giấy phép | C6: Phòng khám Chuyên khoa Da liễu Lạc's Beauty Center | D6: Chân trang | E6: Đối chiếu đúng tên trên giấy phép.
A7: Pháp lý | B7: Số giấy phép hoạt động KCB – ngày cấp – cơ quan cấp (CS01) | D7: Chân trang, Giấy phép
A8: Pháp lý | B8: Số giấy phép hoạt động KCB (CS02) | D8: Chân trang, Giấy phép | E8: Nếu CS02 có giấy phép riêng.
A9: Pháp lý | B9: Người chịu trách nhiệm chuyên môn kỹ thuật | D9: Chân trang
A10: Pháp lý | B10: GCN đủ điều kiện kinh doanh dược (Nhà thuốc) | D10: Trang Nhà thuốc, Giấy phép
A11: Pháp lý | B11: Giấy phép / mã ngành đào tạo (Academy) | D11: Trang Đào tạo | E11: Đào tạo sơ cấp Chăm sóc da.
A12: Pháp lý | B12: Thông báo website TMĐT với Bộ Công Thương | D12: Chân trang (logo) | E12: Thực hiện sau khi có đủ trang chính sách.
A13: Cơ sở | B13: Cơ sở 01 – địa chỉ đầy đủ | C13: Số 231T, Đường 3/2, Phường Tân An, Thành phố Cần Thơ, Việt Nam | D13: Chân trang, Hệ thống cơ sở, Liên hệ
A14: Cơ sở | B14: Cơ sở 01 – giờ làm việc | C14: 8:00 - 20:00 | D14: Như trên
A15: Cơ sở | B15: Cơ sở 01 – link Google Maps + mã nhúng | D15: Hệ thống cơ sở, Liên hệ
A16: Cơ sở | B16: Cơ sở 02 – địa chỉ đầy đủ | C16: 388 NVC (cần ghi đầy đủ tên đường, phường, TP) | D16: Như trên | E16: Khai trương 29/09/2026.
A17: Cơ sở | B17: Cơ sở 02 – giờ làm việc | D17: Như trên
A18: Cơ sở | B18: Cơ sở 02 – link Google Maps + mã nhúng | D18: Như trên
A19: Liên hệ | B19: Hotline đặt lịch | D19: Đầu trang, nút nổi, chân trang
A20: Liên hệ | B20: Hotline nhà thuốc / mua hàng (nếu khác) | D20: Trang sản phẩm, chân trang
A21: Liên hệ | B21: Email | D21: Chân trang, Liên hệ
A22: Liên hệ | B22: Zalo OA / Zalo phòng khám | D22: Nút nổi, chân trang | E22: Kênh của phòng khám, không dùng Zalo cá nhân.
A23: Liên hệ | B23: Messenger (Fanpage phòng khám) | D23: Nút nổi
A24: Liên hệ | B24: Nơi nhận lead form Đặt lịch | D24: — | E24: Email nhận / Pancake / CSKH – theo quy tắc phân lead (sheet 13).
A25: Mạng xã hội | B25: Fanpage Phòng khám Da liễu Lạc's Beauty Center | D25: Chân trang
A26: Mạng xã hội | B26: Fanpage Lạc's Academy | D26: Trang Đào tạo, chân trang
A27: Mạng xã hội | B27: TikTok phòng khám | D27: Chân trang
A28: Mạng xã hội | B28: YouTube (nếu có) | D28: Chân trang
A29: Mạng xã hội | B29: Website cá nhân / kênh của bác sĩ (nếu liên kết) | D29: Hồ sơ bác sĩ | E29: Chỉ đặt ở hồ sơ bác sĩ, không đặt ở khu vực sản phẩm (sheet 13).
A30: Sàn TMĐT | B30: Shopee | D30: Chân trang
A31: Sàn TMĐT | B31: TikTok Shop | D31: Chân trang
A32: Sàn TMĐT | B32: Lazada | D32: Chân trang
A33: Sàn TMĐT | B33: Tiki | D33: Chân trang
A34: Bán hàng | B34: Phương thức thanh toán áp dụng trên web | D34: Chân trang, Chính sách thanh toán | E34: Chỉ hiển thị logo phương thức thực sự dùng.
A35: Bán hàng | B35: Đơn vị vận chuyển / phí giao hàng | D35: Chính sách giao hàng
A36: Đo lường | B36: Google Analytics 4 – Measurement ID | D36: Cài đặt Sapo
A37: Đo lường | B37: Google Search Console – xác minh tên miền | D37: Cài đặt Sapo
A38: Đo lường | B38: Google Tag Manager (nếu dùng) | D38: Cài đặt Sapo
A39: Đo lường | B39: Meta Pixel ID | D39: Cài đặt Sapo
A40: Đo lường | B40: Sự kiện chuyển đổi cần theo dõi | C40: Gửi form đặt lịch · Bấm gọi hotline · Bấm Zalo/Messenger · Thêm vào giỏ · Mua hàng | D40: —
...

Sheet 13. Điểm cần xác nhận
A1: 13. CÁC ĐIỂM CẦN XÁC NHẬN TRƯỚC KHI TRIỂN KHAI
A2: Những điểm brief đang tạm đề xuất hoặc thiếu thông tin. Ghi quyết định cuối vào cột E.
A3: STT | B3: Vấn đề | C3: Đề xuất trong brief | D3: Người quyết định | E3: Quyết định cuối | F3: Trạng thái
A4: 1 | B4: Giá trị cốt lõi có 3 ý, module Chính sách của theme có 4 ô. | C4: Ô thứ 4: "Dược mỹ phẩm chính hãng" (đã có trong nội dung website). Phương án khác: "Phác đồ chuẩn y khoa" hoặc chỉnh module còn 3 ô. | D4: Ban Giám đốc | F4: Chưa bắt đầu
A5: 2 | B5: Danh sách và hồ sơ 4 bác sĩ; BS. Lạc Kim Ngân có nằm trong 4 bác sĩ không. | C5: Chờ danh sách chính thức + văn bản đồng ý công khai hình ảnh. | D5: Ban Giám đốc | F5: Chưa bắt đầu
A6: 3 | B6: Danh sách máy móc/công nghệ thực tế và giấy tờ lưu hành. | C6: Sheet 7 đang là khung theo nhóm; chỉ đăng thiết bị có giấy tờ hợp lệ. | D6: Bác sĩ phụ trách chuyên môn | F6: Chưa bắt đầu
A7: 4 | B7: Đào tạo nghề: trang riêng trên lbcgroup.vn hay dẫn sang kênh Lạc's Academy. | C7: Làm 1 trang giới thiệu /dao-tao trên lbcgroup.vn, có form đăng ký tư vấn; lead học viên tách khỏi lead khách khám. | D7: Ban Giám đốc + Marketing | F7: Chưa bắt đầu
A8: 5 | B8: Hiển thị Đội ngũ bác sĩ trên trang chủ: theme không có module riêng. | C8: Dùng Module Tin tức 2 trỏ blog đội ngũ; nếu bố cục không đẹp → chỉnh code nhẹ để hiển thị 4 thẻ ngang (liên hệ hỗ trợ Mr. Bean Themes nếu cần). | D8: Web/SEO | F8: Chưa bắt đầu
A9: 6 | B9: Phông chữ Fraunces + Be Vietnam Pro: theme có thể không hỗ trợ chọn font. | C9: Thêm bằng CSS tùy chỉnh (Google Fonts); kiểm tra tốc độ tải sau khi thêm. | D9: Web/SEO | F9: Chưa bắt đầu
A10: 7 | B10: Logo hiển thị: logo phòng khám Lạc's Beauty Center hay logo LBC Group (tên miền lbcgroup.vn). | C10: Đầu trang dùng logo Lạc's Beauty Center; chân trang ghi tên pháp nhân công ty. | D10: Ban Giám đốc | F10: Chưa bắt đầu
A11: 8 | B11: Giỏ hàng: bán online thật (thanh toán, giao hàng) hay chỉ trưng bày + đặt qua hotline/sàn. | C11: Giữ giỏ hàng, tồn kho web quản lý riêng; nếu chưa sẵn sàng vận hành → dẫn nút mua sang Shopee/TikTok Shop. | D11: Ban Giám đốc + Nhà thuốc | F11: Chưa bắt đầu
